Workbook

Sheet Параметры
A1: Параметр | B1: Значение
A2: Часовая ставка (₽) | B2: 3500
A3: Проект | B3: Grammy
A4: Описание | B4: Telegram-бот продажи доступа в закрытые каналы + админ-панель
A6: Изменение ставки в B2 автоматически пересчитает все стоимости на других листах.

Sheet Сводная
A1: ID | B1: Модуль | C1: Backend | D1: Frontend | E1: Design | F1: DevOps | G1: QA | H1: Всего, ч | I1: Стоимость, ₽ | J1: Пакеты
A2: M01 | B2: Платформа и инфраструктура | C2: 0 | D2: 0 | E2: 0 | F2: 3 | G2: 0 | H2: 3 | I2: =H2*Параметры!$B$2 | J2: base, standard, premium
A3: M02 | B3: Аутентификация и RBAC | C3: 3 | D3: 1 | E3: 0 | F3: 0 | G3: 0 | H3: 4 | I3: =H3*Параметры!$B$2 | J3: base, standard, premium
A4: M03 | B4: Каталог: продукты, каналы, боты | C4: 2 | D4: 3 | E4: 1 | F4: 0 | G4: 0 | H4: 6 | I4: =H4*Параметры!$B$2 | J4: base, standard, premium
A5: M04 | B5: Пользователи и first-touch | C5: 3 | D5: 0 | E5: 0 | F5: 0 | G5: 0 | H5: 3 | I5: =H5*Параметры!$B$2 | J5: base, standard, premium
A6: M05 | B6: Заявки (Leads) | C6: 2 | D6: 2 | E6: 0 | F6: 0 | G6: 0 | H6: 4 | I6: =H6*Параметры!$B$2 | J6: base, standard, premium
A7: M06 | B7: Платежи и подписки | C7: 5 | D7: 2 | E7: 1 | F7: 0 | G7: 0 | H7: 8 | I7: =H7*Параметры!$B$2 | J7: base, standard, premium
A8: M11 | B8: Telegram-бот (aiogram, multi-bot) | C8: 5 | D8: 0 | E8: 0 | F8: 0 | G8: 0 | H8: 5 | I8: =H8*Параметры!$B$2 | J8: base, standard, premium
A9: M12 | B9: Админ-панель UI/UX (база) | C9: 0 | D9: 3 | E9: 1 | F9: 0 | G9: 0 | H9: 4 | I9: =H9*Параметры!$B$2 | J9: base, standard, premium
A10: M13 | B10: Брендинг и SEO | C10: 0 | D10: 0 | E10: 3 | F10: 0 | G10: 0 | H10: 3 | I10: =H10*Параметры!$B$2 | J10: base, standard, premium
A11: ИТОГО | B11: Все модули (полная комплектация) | C11: =SUM(C2:C10) | D11: =SUM(D2:D10) | E11: =SUM(E2:E10) | F11: =SUM(F2:F10) | G11: =SUM(G2:G10) | H11: =SUM(H2:H10) | I11: =H11*Параметры!$B$2

Sheet Детализация
A1: Модуль ТЗ | B1: Задача | C1: Backend | D1: Frontend | E1: Design | F1: DevOps | G1: QA | H1: Всего, ч | I1: Стоимость, ₽
A2: M01. Платформа и инфраструктура
A3: M01 | B3: Docker Compose: db / backend / admin / nginx / certbot | F3: 3 | H3: 3 | I3: =H3*Параметры!$B$2
A4: M01 | B4: Healthcheck Postgres + /api/healthz endpoint | H4: 0 | I4: =H4*Параметры!$B$2
A5: M01 | B5: Nginx-конфиг с SSL termination и проксированием | H5: 0 | I5: =H5*Параметры!$B$2
A6: M01 | B6: Certbot webroot + auto-renew | H6: 0 | I6: =H6*Параметры!$B$2
A7: M01 | B7: Cron daily docker cleanup | H7: 0 | I7: =H7*Параметры!$B$2
A8: M01 | B8: .env / .env.example / документация переменных | H8: 0 | I8: =H8*Параметры!$B$2
B9: Итого M01 | C9: 0 | D9: 0 | E9: 0 | F9: 3 | G9: 0 | H9: 3 | I9: =H9*Параметры!$B$2
A10: M02. Аутентификация и RBAC
A11: M02 | B11: Backend: модель Admin + миграция + bcrypt-утилиты | H11: 0 | I11: =H11*Параметры!$B$2
A12: M02 | B12: Endpoint /auth/login + JWT + cookie + rate-limit | C12: 3 | H12: 3 | I12: =H12*Параметры!$B$2
A13: M02 | B13: Endpoint /auth/me + /auth/logout + смена пароля | H13: 0 | I13: =H13*Параметры!$B$2
A14: M02 | B14: Dependency current_admin + require_role(*) | H14: 0 | I14: =H14*Параметры!$B$2
A15: M02 | B15: Frontend: /login форма + redirect логика | D15: 1 | H15: 1 | I15: =H15*Параметры!$B$2
A16: M02 | B16: Frontend: auth-check в layout, fetch-обёртка с 401 | H16: 0 | I16: =H16*Параметры!$B$2
A17: M02 | B17: UX: пустые поля, ошибки, состояние «вошёл» | H17: 0 | I17: =H17*Параметры!$B$2
B18: Итого M02 | C18: 3 | D18: 1 | E18: 0 | F18: 0 | G18: 0 | H18: 4 | I18: =H18*Параметры!$B$2
A19: M03. Каталог: продукты, каналы, боты
A20: M03 | B20: Backend: модели Bot/Channel/Product + миграции | H20: 0 | I20: =H20*Параметры!$B$2
A21: M03 | B21: Backend API /bots (CRUD, getMe-валидация, sync polling) | C21: 1 | H21: 1 | I21: =H21*Параметры!$B$2
A22: M03 | B22: Backend API /channels (CRUD, проверка прав бота) | H22: 0 | I22: =H22*Параметры!$B$2
A23: M03 | B23: Backend API /products (CRUD, code-unique, collision-check) | C23: 1 | H23: 1 | I23: =H23*Параметры!$B$2
A24: M03 | B24: Frontend: страница /bots | D24: 1 | H24: 1 | I24: =H24*Параметры!$B$2
A25: M03 | B25: Frontend: страница /channels | D25: 1 | H25: 1 | I25: =H25*Параметры!$B$2
A26: M03 | B26: Frontend: страница /products + детали + ссылки | D26: 1 | H26: 1 | I26: =H26*Параметры!$B$2
A27: M03 | B27: Дизайн: формы CRUD, пустые состояния, badges | E27: 1 | H27: 1 | I27: =H27*Параметры!$B$2
B28: Итого M03 | C28: 2 | D28: 3 | E28: 1 | F28: 0 | G28: 0 | H28: 6 | I28: =H28*Параметры!$B$2
A29: M04. Пользователи и first-touch
A30: M04 | B30: Backend: модель User + first_* поля + миграции | C30: 3 | H30: 3 | I30: =H30*Параметры!$B$2
A31: M04 | B31: Backend: идемпотентная функция _set_first_touch | H31: 0 | I31: =H31*Параметры!$B$2
A32: M04 | B32: Backend API /users (поиск, профиль с JOIN) | H32: 0 | I32: =H32*Параметры!$B$2
A33: M04 | B33: Frontend: /users со строкой поиска | H33: 0 | I33: =H33*Параметры!$B$2
A34: M04 | B34: Frontend: /users/[id] с тремя вкладками истории | H34: 0 | I34: =H34*Параметры!$B$2
A35: M04 | B35: Дизайн: профиль пользователя | H35: 0 | I35: =H35*Параметры!$B$2
B36: Итого M04 | C36: 3 | D36: 0 | E36: 0 | F36: 0 | G36: 0 | H36: 3 | I36: =H36*Параметры!$B$2
A37: M05. Заявки (Leads)
A38: M05 | B38: Backend: модель Lead + миграция + FSM | H38: 0 | I38: =H38*Параметры!$B$2
A39: M05 | B39: Backend API /leads (CRUD, фильтр, экспорт CSV) | C39: 2 | H39: 2 | I39: =H39*Параметры!$B$2
A40: M05 | B40: Frontend: /leads с табами + badge в sidebar | D40: 1 | H40: 1 | I40: =H40*Параметры!$B$2
...

Sheet Пакеты
A1: Пакет | B1: Описание | C1: Состав (модули) | D1: Всего, ч | E1: Стоимость, ₽
A2: Базовый (MVP) | B2: Минимально жизнеспособный продукт: можно подключить ботов и каналы, продавать продукты, обрабатывать заявки и платежи вручную, выдавать доступ. Без воронок, без полноценной аналитики, без observability. | C2: M01, M02, M03, M04, M05, M06, M11, M12, M13 | D2: 40 | E2: =D2*Параметры!$B$2
A3: Стандарт | B3: Базовый + автоматизация и аналитика: воронки прогрева, tracking-ссылки и UTM, лидмагниты, страница аналитики с фильтрами и графиками, наблюдаемость с алертами. Готовый production-инструмент инфобиз-команды. | C3: M01, M02, M03, M04, M05, M06, M11, M12, M13 | D3: 40 | E3: =D3*Параметры!$B$2
A4: Премиум | B4: Стандарт + полноценный compliance и QA: журнал действий с маскированием секретов, полное покрытие тестами (backend ~470, frontend ~28, e2e 6), CI/CD с 5 jobs, pre-commit, security-сканирование. | C4: M01, M02, M03, M04, M05, M06, M11, M12, M13 | D4: 40 | E4: =D4*Параметры!$B$2

Sheet Матрица
A1: Модуль | B1: Базовый (MVP) | C1: Стандарт | D1: Премиум
A2: M01. Платформа и инфраструктура | B2: ✓ | C2: ✓ | D2: ✓
A3: M02. Аутентификация и RBAC | B3: ✓ | C3: ✓ | D3: ✓
A4: M03. Каталог: продукты, каналы, боты | B4: ✓ | C4: ✓ | D4: ✓
A5: M04. Пользователи и first-touch | B5: ✓ | C5: ✓ | D5: ✓
A6: M05. Заявки (Leads) | B6: ✓ | C6: ✓ | D6: ✓
A7: M06. Платежи и подписки | B7: ✓ | C7: ✓ | D7: ✓
A8: M11. Telegram-бот (aiogram, multi-bot) | B8: ✓ | C8: ✓ | D8: ✓
A9: M12. Админ-панель UI/UX (база) | B9: ✓ | C9: ✓ | D9: ✓
A10: M13. Брендинг и SEO | B10: ✓ | C10: ✓ | D10: ✓
